<?xml version="1.0" ?>
<!-- =================================================================================== -->
<!-- |    This document was autogenerated by xacro from kani.urdf.xacro                | -->
<!-- |    EDITING THIS FILE BY HAND IS NOT RECOMMENDED                                 | -->
<!-- =================================================================================== -->
<robot name="kani" xmlns:xacro="http://www.ros.org/wiki/xacro">
  <!-- <xacro:include filename="$(find kani_description)/urdf/base.transmission.xacro"/> -->
  <!-- <xacro:include filename="$(find kani_description)/urdf/base.gazebo.xacro" /> -->
  <!-- <xacro:macro name="kani_lwheel_trans">
    <transmission name="lwheel_trans" type="SimpleTransmission">
      <type>transmission_interface/SimpleTransmission</type>
      <joint name="lwheel_joint">
        <hardwareInterface>VelocityJointInterface</hardwareInterface>
      </joint>
      <actuator name="lwheel_motor">
        <mechanicalReduction>1</mechanicalReduction>
        <hardwareInterface>VelocityJointInterface</hardwareInterface>
      </actuator>
    </transmission>
  </xacro:macro> -->
  <!-- 
  <xacro:macro name="kani_lwheel_gazebo">
    <gazebo reference="left_wheel">
      <material>Gazebo/Black</material>
      <mu1 value="100.0"/>
      <mu2 value="100.0"/>
      <kp value="1000000.0" />
      <kd value="1.0" />
      <fdir1 value="1 0 0"/>
      <dampingFactor value="0.1"/>
    </gazebo>
  </xacro:macro> -->
  <link name="base_footprint">
    <visual>
      <origin rpy="0 0 0" xyz="0 0 0"/>
      <geometry>
        <box size="0.001 0.001 0.001"/>
      </geometry>
    </visual>
  </link>
  <joint name="base_footprint_joint" type="fixed">
    <origin rpy="0 0 0" xyz="0 0 0"/>
    <child link="base_link"/>
    <parent link="base_footprint"/>
  </joint>
  <link name="base_link">
    <inertial>
      <origin rpy="0 0 0" xyz="0.0 0.0 0.0"/>
      <mass value="0.05"/>
      <inertia ixx="0.2" ixy="0" ixz="0" iyy="0.2" iyz="0" izz="0.2"/>
    </inertial>
    <visual>
      <origin rpy="-1.57079632679 0 0" xyz="0 0 0"/>
      <geometry>
        <mesh filename="package://kani_description/STL/base.stl"/>
      </geometry>
      <!-- <material>
        </material> -->
    </visual>
    <collision>
      <origin rpy="0 0 0" xyz="0 0 0"/>
      <geometry>
        <mesh filename="package://kani_description/STL/base.stl"/>
      </geometry>
      <!-- <material>
        </material> -->
    </collision>
  </link>
  <!-- Wheel macros -->
  <!-- <xacro:rwheel />
    <xacro:lwheel /> -->
  <!-- Hokuyo utm30lx-->
  <!-- <xacro:hokuyo_utm30lx name="hokuyo" parent="base_link"/> -->
  <!-- <xacro:hokuyo_utm30lx_back name="hokuyo_back" parent="base_link"/> -->
  <!-- Extensions -->
  <!-- <xacro:kani_base_gazebo/> -->
  <link name="rightFront_link">
    <inertial>
      <origin rpy="0 0 0" xyz="0 0 0"/>
      <!--0.00222524026865972 0.173009757872407 -0.000157420245397055-->
      <mass value="0.0963917377366023"/>
      <inertia ixx="0.232225456967381" ixy="0.0" ixz="0.0" iyy="0.232225456967381" iyz="0.0" izz="0.232225456967381"/>
    </inertial>
    <visual>
      <origin rpy="0 0 0" xyz="0 0 0"/>
      <geometry>
        <mesh filename="package://kani_description/STL/wheel_link.stl"/>
      </geometry>
      <material name="black">
        </material>
    </visual>
    <collision>
      <origin rpy="0 0 0" xyz="0 0 0"/>
      <geometry>
        <mesh filename="package://kani_description/STL/wheel_link.stl"/>
      </geometry>
    </collision>
  </link>
  <joint name="rightFront_joint" type="continuous">
    <origin rpy="0 0 0" xyz="0 0 0"/>
    <!-- xyz= "0.0600000000000003 -0.178955289353836 -0.0124450740677247" -->
    <parent link="base_link"/>
    <child link="rightFront_link"/>
    <axis xyz="0 1 0"/>
  </joint>
  <gazebo reference="rightFront">
    <material>Gazebo/Black</material>
    <mu1 value="100.0"/>
    <mu2 value="100.0"/>
    <kp value="1000000.0"/>
    <kd value="1.0"/>
    <fdir1 value="1 0 0"/>
    <dampingFactor value="0.1"/>
  </gazebo>
  <transmission name="rightFront" type="SimpleTransmission">
    <type>transmission_interface/SimpleTransmission</type>
    <joint name="rightFront_joint">
      <hardwareInterface>VelocityJointInterface</hardwareInterface>
    </joint>
    <actuator name="rightFront_motor">
      <mechanicalReduction>1</mechanicalReduction>
      <hardwareInterface>VelocityJointInterface</hardwareInterface>
    </actuator>
  </transmission>
  <link name="leftFront_link">
    <inertial>
      <origin rpy="0 0 0" xyz="0 0 0"/>
      <!--0.00222524026865972 0.173009757872407 -0.000157420245397055-->
      <mass value="0.0963917377366023"/>
      <inertia ixx="0.232225456967381" ixy="0.0" ixz="0.0" iyy="0.232225456967381" iyz="0.0" izz="0.232225456967381"/>
    </inertial>
    <visual>
      <origin rpy="0 0 0" xyz="0 0 0"/>
      <geometry>
        <mesh filename="package://kani_description/STL/wheel_link.stl"/>
      </geometry>
      <material name="black">
        </material>
    </visual>
    <collision>
      <origin rpy="0 0 0" xyz="0 0 0"/>
      <geometry>
        <mesh filename="package://kani_description/STL/wheel_link.stl"/>
      </geometry>
    </collision>
  </link>
  <joint name="leftFront_joint" type="continuous">
    <origin rpy="0 0 0" xyz="10 10 0"/>
    <!-- xyz= "0.0600000000000003 -0.178955289353836 -0.0124450740677247" -->
    <parent link="base_link"/>
    <child link="leftFront_link"/>
    <axis xyz="0 1 0"/>
  </joint>
  <gazebo reference="leftFront">
    <material>Gazebo/Black</material>
    <mu1 value="100.0"/>
    <mu2 value="100.0"/>
    <kp value="1000000.0"/>
    <kd value="1.0"/>
    <fdir1 value="1 0 0"/>
    <dampingFactor value="0.1"/>
  </gazebo>
  <transmission name="leftFront" type="SimpleTransmission">
    <type>transmission_interface/SimpleTransmission</type>
    <joint name="leftFront_joint">
      <hardwareInterface>VelocityJointInterface</hardwareInterface>
    </joint>
    <actuator name="leftFront_motor">
      <mechanicalReduction>1</mechanicalReduction>
      <hardwareInterface>VelocityJointInterface</hardwareInterface>
    </actuator>
  </transmission>
</robot>

